Workbook

Sheet Instructions
A1: SMS ROOFING — MECHANICALLY ATTACHED TPO • LOCKED ESTIMATING TEMPLATE
A2: Scope: mech-attached polyiso · mech-attached 60-mil TPO field · fully adhered TPO walls up-and-over · perimeter flat metal · penetrations and accessories. TEAR-OFF.
A4: THE PAGES — in the order you work them
A5: 1 · Takeoff | B5: THE DUMP. Only what you measure or count off the plans. Roof areas, counts, wall facets, coping / gravel stop / counter flashing / downspout runs, curbs. No materials. No pricing. Nothing derived.
A6: 2 · Material Order | B6: The order list. Every quantity reads live off the Material Takeoff page. Under each line, in plain words, is why that number is what it is — so somebody who has never been on a roof can read it and know what to change.
A7: 3 · Labor | B7: Crew cost per day ÷ squares per day = $ per square. Plus the unit-priced lines.
A8: 4 · Totals | B8: Material markup applied to material only. TOTAL BID and price per square.
A9: At the far right | B9: Plan Reference — the wall sections and kicker widths this job was read off. Material Takeoff — the working math behind every quantity on the order.
A11: HOW A LINE WORKS ON PAGE 2
A12: The pattern | B12: DRIVER x / ÷ FACTOR = RAW → QTY. The driver reads live off the Takeoff page. The FACTOR is the only cell you touch.
A13: Why | B13: Change one factor and every number downstream moves. Nothing is ever typed twice, and nothing is typed that could be calculated.
A14: The test | B14: Somebody who has never been on that roof fills in page 1 and the whole bid falls out.
A16: LEGEND
A17: Blue text | B17: Editable input — type here
A18: Green text | B18: Live link — pulls from another page. Never edit.
A19: Black text | B19: Locked formula
A20: Red text | B20: RAW / unrounded — what the math produced before rounding up to a whole package
A21: Yellow fill | B21: THE EQUATION GOES HERE — factor, divisor or rate, still to be set
A22: Blue narrow band | B22: Explains the section above in live numbers
A24: STATUS
A25: Where this stands | B25: Every product line is in place and every page is wired to the one before it. Nothing is priced and nothing is assumed.
A26: What is left | B26: Fill the yellow cells line by line. Each one is a rule stated once, then locked.
A27: If something is wrong | B27: If a product is missing, sits on the wrong page, or should not be on a mech-attached TPO job — say so and it moves or comes out.
A29: THE RULE ABOUT RULES
A30: Where equations come from | B30: Adam states them. They get built. Nothing is derived, assumed or back-filled from a number that looks close.
A31: Checks & balances | B31: Section K on the Takeoff page. Only checks Adam has stated go there — an invented check costs more to undo than it ever saved.
A32: Who this is for | B32: Adam, but also whoever runs it after him. It has to work for someone who does not know roofing.

Sheet Existing
A1: EXISTING CONDITIONS — 9506 BAMBOO, HOUSTON · WORTHAM BROTHERS
A2: Answer this page first. A question only shows up when it applies — a greyed cell is not being asked, leave it alone. How each layer is stuck down is what drives the TEAR-OFF LABOR and what shape the deck is in when it is exposed.
A4: A · WHAT KIND OF JOB IS THIS
A5: Item | B5: Answer | H5: What it turns on
A6: Construction type | H6: =IF($B$6="","pick one — nothing below this matters until you do",IF($B$6="New construction","NEW CONSTRUCTION — no existing roof. Everything below switches off.",IF($B$6="Recover","RECOVER — the existing roof stays. Still answer the layers: what stays under the new roof drives the fastener length.","TEAR OFF — every layer below is a layer that has to come off.")))
A8: B · THE DECK
A9: Item | B9: Answer | C9: Unit | H9: Note
A10: Decking | H10: the bottom of the stack. Everything above is measured from here up.
A11: =IF(OR(ISNUMBER(SEARCH("lightweight",$B$10)),ISNUMBER(SEARCH("lwic",$B$10))),"Lightweight concrete thickness","") | C11: =IF(OR(ISNUMBER(SEARCH("lightweight",$B$10)),ISNUMBER(SEARCH("lwic",$B$10))),"in","") | H11: =IF(OR(ISNUMBER(SEARCH("lightweight",$B$10)),ISNUMBER(SEARCH("lwic",$B$10))),"how thick the lightweight is. A screw has to pass through all of it to reach the steel.","not asked — the deck is not lightweight concrete")
A12: =IF(ISNUMBER(SEARCH("wood",$B$10)),"Wood deck material","") | C12: =IF(ISNUMBER(SEARCH("wood",$B$10)),"","") | H12: =IF(ISNUMBER(SEARCH("wood",$B$10)),"OSB, planks or plywood — it changes the fastener.","not asked — the deck is not wood")
A13: =IF(AND(ISNUMBER(SEARCH("steel",$B$10)),NOT(OR(ISNUMBER(SEARCH("lightweight",$B$10)),ISNUMBER(SEARCH("lwic",$B$10))))),"Steel deck profile","") | H13: =IF(AND(ISNUMBER(SEARCH("steel",$B$10)),NOT(OR(ISNUMBER(SEARCH("lightweight",$B$10)),ISNUMBER(SEARCH("lwic",$B$10))))),"R panel or B deck — the flute is what the screw lands in.","not asked — the deck is not steel")
A15: C · EXISTING ROOF LAYERS — from the deck up
A16: One question at a time, left to right. Roof type → how it is attached → gravel if it is a built-up → is there insulation under it → if yes, how the board is attached and how thick it is. Greyed = not asked. THREE LAYERS IS NOT CODE — three means tearing off is the only option.
A17: Layer | B17: Roof type | C17: Attachment | D17: Gravel? | E17: Insulation? (what board) | F17: Board attachment | G17: Board thickness (in) | H17: Note
A18: Layer 1 (on the deck) | H18: =IF($B$6="New construction","n/a — new construction has no existing layers",IF(B18="","start here — what is sitting on the deck",IF(C18="","→ how is it attached?",IF(AND(UPPER(B18)="BUR",D18=""),"→ gravel on it? Y or N",IF(E18="","→ what board is under it? N/A if none",IF(AND(UPPER(E18)<>"N/A",F18=""),"→ how is that board attached?",IF(AND(UPPER(E18)<>"N/A",G18=""),"→ how thick is that board?","done")))))))
A19: Layer 2 | H19: =IF($B$6="New construction","n/a — new construction has no existing layers",IF(B18="","answer Layer 1 first",IF(B19="","open — name it, or mark N/A if there is no Layer 2",IF(UPPER(B19)="N/A","no Layer 2. The stack stops at Layer 1.",IF(C19="","→ how is it attached?",IF(AND(UPPER(B19)="BUR",D19=""),"→ gravel on it? Y or N",IF(E19="","→ what board is under it? N/A if none",IF(AND(UPPER(E19)<>"N/A",F19=""),"→ how is that board attached?",IF(AND(UPPER(E19)<>"N/A",G19=""),"→ how thick is that board?","done")))))))))
A20: Layer 3 | H20: =IF($B$6="New construction","n/a — new construction has no existing layers",IF(B19="","answer Layer 2 first",IF(B20="","open — name it, or mark N/A if there is no Layer 3",IF(UPPER(B20)="N/A","no Layer 3. The stack stops at Layer 2.",IF(C20="","→ how is it attached?",IF(AND(UPPER(B20)="BUR",D20=""),"→ gravel on it? Y or N",IF(E20="","→ what board is under it? N/A if none",IF(AND(UPPER(E20)<>"N/A",F20=""),"→ how is that board attached?",IF(AND(UPPER(E20)<>"N/A",G20=""),"→ how thick is that board?","done")))))))))
A21: Layers counted | B21: =IF($B$6="New construction",0,COUNTIFS(B18:B20,"<>")-COUNTIFS(B18:B20,"N/A")) | H21: =IF($B$6="New construction","",IF(B21=0,"",IF(B21>=3,"THREE LAYERS. That is not code. Tear-off is the only option — a recover is off the table.",IF($B$6="Recover","recover: these layers stay put and the new roof goes over them","tear off: every layer above has to come off"))))
A27: What the new roof is and how it attaches is answered on the TAKEOFF tab, section A · SETUP. It is not asked twice.

Sheet Takeoff
A1: SMS ROOFING — 9506 BAMBOO, HOUSTON · WORTHAM BROTHERS · TAKEOFF
A2: PAGE ONE. The dump. Everything here comes off the plans or the takeoff app. Nothing is derived, nothing is priced.
A3: JOB: __________ · __________ · __________
A4: A · SETUP — what this roof IS. Everything below funnels off these.
A5: "This is the assembly, not a measurement. None of it comes off the takeoff — it comes off the spec and the manufacturer. Change the fastening pattern for a higher wind uplift and nothing else about the system changes: same sheet, same everything, different pattern."
A6: Item | B6: Value | C6: Unit | J6: Note
A7: System
A8: Deck type
A9: Lightweight concrete thickness | C9: in | J9: =IF(OR(ISNUMBER(SEARCH("lightweight",$B$8)),ISNUMBER(SEARCH("lwic",$B$8))),"how thick the lightweight pour is. A screw has to pass through all of it to reach the metal pan, so this sets the fastener length. 2 in is the usual pour.","not asked — this only comes up when the deck is lightweight concrete")
A10: Insulation thickness | C10: in
A11: Fall — where does it come from?
A12: Membrane thickness | C12: mil
A13: Field membrane sheet width (ft) | C13: ft | J13: VARIABLE — what sheet the FIELD gets is up to the job and the system. It has nothing to do with the wall, which is fastened every 5 ft no matter what sheet runs on it.
A14: ISO plates per board | C14: ea | J14: VARIABLE — ask the manufacturer for THIS system. Nothing prices until it is answered.
A15: Wall fastener spacing | C15: in o.c. | J15: THE WIND-UPLIFT LEVER — tighten this and only the fastener count moves
A16: Base flashing fastener spacing | C16: in o.c.
A18: B · ROOF AREA
A19: Item | B19: Value | C19: Unit | J19: Note
A20: Field squares | C20: sf | J20: the net field — membrane and cover board both follow this
A21: Perimeter base flashing | C21: LF | J21: HAND COUNT off the plan. Do not derive it.
A22: Curb flashing | C22: LF | E22: Curbs (count) | J22: total curb perimeter off the takeoff app — every curb added up. The COUNT beside it drives the corners.
A24: C · COUNTS — straight from the takeoff
A25: Item | B25: Qty | C25: Unit | J25: Note
A26: Curb flashing | B26: =IFERROR(IF(B22="","",B22),"") | C26: LF | J26: reads the curb flashing LF from section B — do not type it twice
A27: Pitch pans | C27: ea
A28: Pipe boots | C28: ea
A29: Scuppers | C29: ea
A30: Collector heads | C30: ea
A31: Roof hatches | C31: ea
A32: Walkpads | C32: LF
A33: Length of cricket wall | C33: LF
A34: Drains | C34: ea | J34: count off the takeoff app. On this roof they cannot be sumped — the deck already falls and the field is one flat layer.
A35: D · PARAPET WALLS — one row per facet, lumped by shared detail
A36: "DEVELOPED = the parapet above the deck + the cap width. That is the face the membrane has to cover." | N36: set this once and every wall uses it. Leave a wall blank to follow it; type on a wall to override just that one.
A37: Wall facet / section mark | B37: Length (ft) | C37: Parapet above deck (ft) | D37: Cap width (ft) | G37: DEVELOPED (ft) | H37: Sq Ft | I37: In perimeter? | J37: Note | K37: Wall substrate | L37: Substrate used
A38: Wall 1 | G38: =IFERROR(IF(AND(C38="",D38=""),"",N(C38)+N(D38)),"") | H38: =IFERROR(IF(OR(B38="",G38=""),0,B38*G38),"") | L38: =IFERROR(IF(B38="","",IF(K38<>"",K38,IF($M$36<>"",$M$36,""))),"")
A39: Wall 2 | G39: =IFERROR(IF(AND(C39="",D39=""),"",N(C39)+N(D39)),"") | H39: =IFERROR(IF(OR(B39="",G39=""),0,B39*G39),"") | L39: =IFERROR(IF(B39="","",IF(K39<>"",K39,IF($M$36<>"",$M$36,""))),"")
A40: Wall 3 | G40: =IFERROR(IF(AND(C40="",D40=""),"",N(C40)+N(D40)),"") | H40: =IFERROR(IF(OR(B40="",G40=""),0,B40*G40),"") | L40: =IFERROR(IF(B40="","",IF(K40<>"",K40,IF($M$36<>"",$M$36,""))),"")
A41: Wall 4 | G41: =IFERROR(IF(AND(C41="",D41=""),"",N(C41)+N(D41)),"") | H41: =IFERROR(IF(OR(B41="",G41=""),0,B41*G41),"") | L41: =IFERROR(IF(B41="","",IF(K41<>"",K41,IF($M$36<>"",$M$36,""))),"")
A42: Wall 5 | G42: =IFERROR(IF(AND(C42="",D42=""),"",N(C42)+N(D42)),"") | H42: =IFERROR(IF(OR(B42="",G42=""),0,B42*G42),"") | L42: =IFERROR(IF(B42="","",IF(K42<>"",K42,IF($M$36<>"",$M$36,""))),"")
...

Sheet Material Order
A1: MATERIAL ORDER — MECHANICALLY ATTACHED TPO
A2: PAGE THREE. Every quantity reads live off the Material Takeoff page. RAW is the number before it rounds up. Prices are yours to set — nothing here is priced by me. The purchased block is what goes to the supplier.
A4: PURCHASED (send to supplier)
A5: Item | B5: RAW (before rounding) | C5: Qty | D5: Unit | E5: Unit $ | F5: Line Total
A6: TPO field membrane 10' | B6: =IFERROR(IF('Material Takeoff'!F28="","",'Material Takeoff'!F28),"") | C6: =IFERROR(IF('Material Takeoff'!G28="","",'Material Takeoff'!G28),"") | D6: roll | E6: =IF(OR(C6="NA",C6="",N(C6)=0),"",IFERROR(IF(VLOOKUP($A6,'Bid Products'!$A$4:$D$60,4,FALSE())="","",VLOOKUP($A6,'Bid Products'!$A$4:$D$60,4,FALSE())),"")) | F6: =IF(OR(C6="NA",C6="",E6=""),"",C6*E6)
A7: ="10 ft roll = 10 squares. 6 in. of it gets lapped over, so 5% is gone, plus "&TEXT('Material Takeoff'!D28,"0%")&" for cuts. Interior "&TEXT(N('Material Takeoff'!B28),"0")&" sq x "&TEXT('Material Takeoff'!E28,"0.00")&" ÷ 10 = "&TEXT(N('Material Takeoff'!G28),"0")&" rolls."
A8: TPO field membrane 5' | B8: =IFERROR(IF('Material Takeoff'!F29="","",'Material Takeoff'!F29),"") | C8: =IFERROR(IF('Material Takeoff'!G29="","",'Material Takeoff'!G29),"") | D8: roll | E8: =IF(OR(C8="NA",C8="",N(C8)=0),"",IFERROR(IF(VLOOKUP($A8,'Bid Products'!$A$4:$D$60,4,FALSE())="","",VLOOKUP($A8,'Bid Products'!$A$4:$D$60,4,FALSE())),"")) | F8: =IF(OR(C8="NA",C8="",E8=""),"",C8*E8)
A9: ="5 ft roll = 5 squares. 6 in. of it gets lapped over, so 10% is gone, plus "&TEXT('Material Takeoff'!D29,"0%")&" for cuts. Perimeter "&TEXT(N('Material Takeoff'!B29),"0")&" sq x "&TEXT('Material Takeoff'!E29,"0.00")&" ÷ 5 = "&TEXT(N('Material Takeoff'!G29),"0")&" rolls."
A10: TPO wall membrane 5' | B10: =IFERROR(IF('Material Takeoff'!F30="","",'Material Takeoff'!F30),"") | C10: =IFERROR(IF('Material Takeoff'!G30="","",'Material Takeoff'!G30),"") | D10: roll | E10: =IF(OR(C10="NA",C10="",N(C10)=0),"",IFERROR(IF(VLOOKUP("TPO wall membrane 5'",'Bid Products'!$A$4:$D$60,4,FALSE())="","",VLOOKUP("TPO wall membrane 5'",'Bid Products'!$A$4:$D$60,4,FALSE())),"")) | F10: =IF(OR(C10="NA",C10="",E10=""),"",C10*E10)
A11: ="Same 5 ft roll. Walls take "&TEXT('Material Takeoff'!D30,"0%")&" for cuts. Walls "&TEXT(N('Material Takeoff'!B30),"0")&" sq x "&TEXT('Material Takeoff'!E30,"0.00")&" ÷ 5 = "&TEXT(N('Material Takeoff'!G30),"0")&" rolls."
A12: Polyiso — field of the roof | B12: =IFERROR(IF('Material Takeoff'!F14="","",'Material Takeoff'!F14),"") | C12: =IFERROR(IF('Material Takeoff'!G14="","",'Material Takeoff'!G14),"") | D12: board | E12: =IF(OR(C12="NA",C12="",N(C12)=0),"",IFERROR(IF(VLOOKUP($A12,'Bid Products'!$A$4:$D$60,4,FALSE())="","",VLOOKUP($A12,'Bid Products'!$A$4:$D$60,4,FALSE())),"")) | F12: =IF(OR(C12="NA",C12="",E12=""),"",C12*E12)
A13: ="3 boards a square. Flat — no waste added. "&TEXT(N('Material Takeoff'!B14),"0")&" sq x 3 = "&TEXT(N('Material Takeoff'!G14),"0")&" boards"
A15: Crickets — Units · Q board | B15: =IFERROR(IF('Material Takeoff'!B22="","",'Material Takeoff'!B22),"") | C15: =IFERROR(IF('Material Takeoff'!G22="","",'Material Takeoff'!G22),"") | D15: board | E15: =IF(OR(C15="NA",C15="",N(C15)=0),"",IFERROR(IF(VLOOKUP($A15,'Bid Products'!$A$4:$D$60,4,FALSE())="","",VLOOKUP($A15,'Bid Products'!$A$4:$D$60,4,FALSE())),"")) | F15: =IF(OR(C15="NA",C15="",E15=""),"",C15*E15)
A16: ="52 unit curbs x 4 corners = "&TEXT(N(Takeoff!F22)*4,"0")&" corners. Check that against the TPO corners line below — the two have to agree. Pull this line and the unit crickets come out of the quote."
A17: Crickets — Scuppers / Drains · Q board | B17: =IFERROR(IF('Material Takeoff'!B23="","",'Material Takeoff'!B23),"") | C17: =IFERROR(IF('Material Takeoff'!G23="","",'Material Takeoff'!G23),"") | D17: board | E17: =IF(OR(C17="NA",C17="",N(C17)=0),"",IFERROR(IF(VLOOKUP($A17,'Bid Products'!$A$4:$D$60,4,FALSE())="","",VLOOKUP($A17,'Bid Products'!$A$4:$D$60,4,FALSE())),"")) | F17: =IF(OR(C17="NA",C17="",E17=""),"",C17*E17)
A18: Crickets — Scuppers / Drains · 2″ fill board 4 ft x 4 ft | B18: =IFERROR(IF('Material Takeoff'!D23="","",'Material Takeoff'!D23),"") | C18: =IFERROR(IF('Material Takeoff'!D23="","",'Material Takeoff'!D23),"") | D18: board | E18: =IF(OR(C18="NA",C18="",N(C18)=0),"",IFERROR(IF(VLOOKUP($A18,'Bid Products'!$A$4:$D$60,4,FALSE())="","",VLOOKUP($A18,'Bid Products'!$A$4:$D$60,4,FALSE())),"")) | F18: =IF(OR(C18="NA",C18="",E18=""),"",C18*E18)
A19: ="7 crickets that steer water to the scuppers and drains — "&TEXT(N('Material Takeoff'!B23),"0")&" Q board plus "&TEXT(N('Material Takeoff'!D23),"0")&" pieces of 2″ fill at 4 ft x 4 ft. These have to be there."
A21: FASTENERS & PLATES
A22: Item | B22: RAW (before rounding) | C22: Qty | D22: Unit | E22: Unit $ | F22: Line Total
A23: ISO plates | B23: =IFERROR(IF('Material Takeoff'!F41="","",'Material Takeoff'!F41),"") | C23: =IFERROR(IF('Material Takeoff'!G41="","",'Material Takeoff'!G41),"") | D23: box | E23: =IF(OR(C23="NA",C23="",N(C23)=0),"",IFERROR(IF(VLOOKUP("ISO plates",'Bid Products'!$A$4:$D$60,4,FALSE())="","",VLOOKUP("ISO plates",'Bid Products'!$A$4:$D$60,4,FALSE())),"")) | F23: =IF(OR(C23="NA",C23="",E23=""),"",C23*E23)
A24: Seam plates | B24: =IFERROR(IF('Material Takeoff'!F82="","",'Material Takeoff'!F82),"") | C24: =IFERROR(IF('Material Takeoff'!G82="","",'Material Takeoff'!G82),"") | D24: box | E24: =IF(OR(C24="NA",C24="",N(C24)=0),"",IFERROR(IF(VLOOKUP("Seam plates",'Bid Products'!$A$4:$D$60,4,FALSE())="","",VLOOKUP("Seam plates",'Bid Products'!$A$4:$D$60,4,FALSE())),"")) | F24: =IF(OR(C24="NA",C24="",E24=""),"",C24*E24)
A25: ="Rolls x 100, plus curb, boots x 4, pans x 4, wall rows and base flashing. All of it x 1.1 = "&TEXT(N('Material Takeoff'!F82),"#,##0")&" plates. One plate, one buy."
A26: TOTAL FASTENERS | B26: =IFERROR(IF('Material Takeoff'!F91="","",'Material Takeoff'!F91),"") | F26: =IF(OR(C26="NA",C26="",E26=""),"",C26*E26)
A27: Insulation fasteners #12 | B27: =IFERROR(IF('Material Takeoff'!F87="","",'Material Takeoff'!F87),"") | C27: =IFERROR(IF('Material Takeoff'!G87="","",'Material Takeoff'!G87),"") | D27: box | E27: =IF(OR(C27="NA",C27="",N(C27)=0),"",IFERROR(IF(VLOOKUP("Insulation fasteners #12",'Bid Products'!$A$4:$D$60,4,FALSE())="","",VLOOKUP("Insulation fasteners #12",'Bid Products'!$A$4:$D$60,4,FALSE())),"")) | F27: =IF(OR(C27="NA",C27="",E27=""),"",C27*E27)
A28: ="One screw per ISO plate. "&TEXT(N('Material Takeoff'!B41),"#,##0")&" boards x "&TEXT(N(Takeoff!B14),"0")&" plates a board = "&TEXT(N('Material Takeoff'!F41),"#,##0")&" screws — #"&TEXT(N('Material Takeoff'!B36),"0")&" x "&TEXT(N('Material Takeoff'!B35),"0")&" in."
A29: Seam fasteners #15 — 5" | B29: =IFERROR(IF('Material Takeoff'!F88="","",'Material Takeoff'!F88),"") | C29: =IFERROR(IF('Material Takeoff'!G88="","",'Material Takeoff'!G88),"") | D29: box | E29: =IF(OR(C29="NA",C29="",N(C29)=0),"",IFERROR(IF(VLOOKUP("Seam fasteners #15 — 5""",'Bid Products'!$A$4:$D$60,4,FALSE())="","",VLOOKUP("Seam fasteners #15 — 5""",'Bid Products'!$A$4:$D$60,4,FALSE())),"")) | F29: =IF(OR(C29="NA",C29="",E29=""),"",C29*E29)
A30: ="One screw per seam plate. "&TEXT(IF(ISNUMBER(SEARCH("WOOD",UPPER(Takeoff!L38))),N('Material Takeoff'!F80),N('Material Takeoff'!F82)),"#,##0")&" screws called for, less the "&TEXT(N('Material Takeoff'!F89)+N('Material Takeoff'!F90),"#,##0")&" that go long = "&TEXT(N('Material Takeoff'!F88),"#,##0")&" at 5 in."
A31: Seam fasteners #15 — 7" | B31: =IFERROR(IF('Material Takeoff'!F89="","",'Material Takeoff'!F89),"") | C31: =IFERROR(IF('Material Takeoff'!G89="","",'Material Takeoff'!G89),"") | D31: box | E31: =IF(OR(C31="NA",C31="",N(C31)=0),"",IFERROR(IF(VLOOKUP("Seam fasteners #15 — 7""",'Bid Products'!$A$4:$D$60,4,FALSE())="","",VLOOKUP("Seam fasteners #15 — 7""",'Bid Products'!$A$4:$D$60,4,FALSE())),"")) | F31: =IF(OR(C31="NA",C31="",E31=""),"",C31*E31)
A32: ="For the crickets. This box came OUT of the 5 in. count, not on top of it — the crickets build the insulation up and a 5 in. screw stops short."
A33: Seam fasteners #15 — 8" | B33: =IFERROR(IF('Material Takeoff'!F90="","",'Material Takeoff'!F90),"") | C33: =IFERROR(IF('Material Takeoff'!G90="","",'Material Takeoff'!G90),"") | D33: box | E33: =IF(OR(C33="NA",C33="",N(C33)=0),"",IFERROR(IF(VLOOKUP("Seam fasteners #15 — 8""",'Bid Products'!$A$4:$D$60,4,FALSE())="","",VLOOKUP("Seam fasteners #15 — 8""",'Bid Products'!$A$4:$D$60,4,FALSE())),"")) | F33: =IF(OR(C33="NA",C33="",E33=""),"",C33*E33)
A34: ="Same — out of the 5 in. count, for the deepest part of the crickets."
A36: ADHESIVES
A37: Item | B37: RAW (before rounding) | C37: Qty | D37: Unit | E37: Unit $ | F37: Line Total
A38: Bonding adhesive | B38: =IFERROR(IF('Material Takeoff'!F97="","",'Material Takeoff'!F97),"") | C38: =IFERROR(IF('Material Takeoff'!G97="","",'Material Takeoff'!G97),"") | D38: pail | E38: =IF(OR(C38="NA",C38="",N(C38)=0),"",IFERROR(IF(VLOOKUP("Bonding adhesive",'Bid Products'!$A$4:$D$60,4,FALSE())="","",VLOOKUP("Bonding adhesive",'Bid Products'!$A$4:$D$60,4,FALSE())),"")) | F38: =IF(OR(C38="NA",C38="",E38=""),"",C38*E38)
A39: ="Wall squares plus the curb, ÷ 3. Curb is "&TEXT(N(Takeoff!B26),"#,##0")&" ft x "&TEXT(N('Material Takeoff'!B94),"0")&" ft tall = "&TEXT(N(Takeoff!B26)*N('Material Takeoff'!B94),"#,##0")&" sf. "&TEXT(N('Material Takeoff'!G8),"0")&" sq + "&TEXT(N(Takeoff!B26)*N('Material Takeoff'!B94)/100,"0.00")&" sq ÷ 3 = "&TEXT(N('Material Takeoff'!G97),"0")&" pails"
A40: Rollers | B40: =IFERROR(IF('Material Takeoff'!F108="","",'Material Takeoff'!F108),"") | C40: =IFERROR(IF('Material Takeoff'!G108="","",'Material Takeoff'!G108),"") | D40: ea | E40: =IF(OR(C40="NA",C40="",N(C40)=0),"",IFERROR(IF(VLOOKUP("Rollers",'Bid Products'!$A$4:$D$60,4,FALSE())="","",VLOOKUP("Rollers",'Bid Products'!$A$4:$D$60,4,FALSE())),"")) | F40: =IF(OR(C40="NA",C40="",E40=""),"",C40*E40)
A41: =IF(N('Material Takeoff'!D108)=0,"rule not set yet",IF(RIGHT('Material Takeoff'!E108,1)=".",'Material Takeoff'!E108,'Material Takeoff'!E108&".")&" "&TEXT(N('Material Takeoff'!B108),"#,##0.##")&" ÷ "&TEXT(N('Material Takeoff'!D108),"#,##0.##")&" = "&TEXT(N('Material Takeoff'!G108),"#,##0")&" ea")
A42: Cages | B42: =IFERROR(IF('Material Takeoff'!F109="","",'Material Takeoff'!F109),"") | C42: =IFERROR(IF('Material Takeoff'!G109="","",'Material Takeoff'!G109),"") | D42: ea | E42: =IF(OR(C42="NA",C42="",N(C42)=0),"",IFERROR(IF(VLOOKUP("Cages",'Bid Products'!$A$4:$D$60,4,FALSE())="","",VLOOKUP("Cages",'Bid Products'!$A$4:$D$60,4,FALSE())),"")) | F42: =IF(OR(C42="NA",C42="",E42=""),"",C42*E42)
A43: =IF(N('Material Takeoff'!D109)=0,"rule not set yet",IF(RIGHT('Material Takeoff'!E109,1)=".",'Material Takeoff'!E109,'Material Takeoff'!E109&".")&" "&TEXT(N('Material Takeoff'!B109),"#,##0.##")&" ÷ "&TEXT(N('Material Takeoff'!D109),"#,##0.##")&" = "&TEXT(N('Material Takeoff'!G109),"#,##0")&" ea")
A44: Sticks | B44: =IFERROR(IF('Material Takeoff'!F110="","",'Material Takeoff'!F110),"") | C44: =IFERROR(IF('Material Takeoff'!G110="","",'Material Takeoff'!G110),"") | D44: ea | E44: =IF(OR(C44="NA",C44="",N(C44)=0),"",IFERROR(IF(VLOOKUP("Sticks",'Bid Products'!$A$4:$D$60,4,FALSE())="","",VLOOKUP("Sticks",'Bid Products'!$A$4:$D$60,4,FALSE())),"")) | F44: =IF(OR(C44="NA",C44="",E44=""),"",C44*E44)
...

Sheet TPO Labor
A1: TPO LABOR — MECHANICALLY ATTACHED TPO · TEAR-OFF
A2: One row per trade. Read across: what it costs in labor, what it costs per square, and what travel adds. This page totals TPO ONLY — metal is on its own page.
A4: RATES — the only cells you set are green
A5: Wage per man / day | B5: 270 | D5: OUT OF TOWN? | F5: N
A6: Overhead margin | B6: 0.5 | D6: =IF($F$5="Y","Per diem $ / man / day","Per diem $ / man / day — not asked, this job is local") | F6: 60
A7: COST PER MAN / DAY | B7: =IFERROR(IF(N(B6)=0,"",N(B5)/N(B6)),"") | D7: =IF($F$5="Y","Hotel $ / room / night","Hotel $ / room / night — not asked, this job is local") | F7: 150
D8: =IF($F$5="Y","Travel markup","Travel markup — not asked, this job is local") | F8: 0.3
A9: ="Overhead is a margin, so it DIVIDES: "&TEXT(N(B5),"$#,##0")&" ÷ "&TEXT(N(B6),"0%")&" = "&TEXT(N(B7),"$#,##0")&" a man a day. Travel is OFF until OUT OF TOWN says Y — it is "&IF($F$5="Y","Y, travel is ON.","N, travel is OFF.")
A10: TRADE | B10: MEN | C10: CREW $/DAY | D10: QTY | E10: UNIT | F10: PER DAY | G10: DAYS | H10: LABOR $ | I10: PRICE PER SQUARE | J10: PER DIEM | K10: HOTEL | L10: TRAVEL MKUP | M10: TRADE TOTAL
A11: Field | C11: =IFERROR(N(B11)*N('TPO Labor'!$B$7),"") | D11: =IFERROR('Material Takeoff'!G6,"") | E11: sq | G11: =IFERROR(IF(N(F11)=0,"",N(D11)/N(F11)),"") | H11: =IFERROR(IF(OR(N(G11)=0,N(C11)=0),"",N(G11)*N(C11)),"") | I11: =IFERROR(IF(N(D11)=0,"",N(H11)/N(D11)),"") | J11: =IFERROR(IF(OR(N(B11)=0,N(G11)=0),"",N(B11)*N(G11)*N('TPO Labor'!$F$6))*IF('TPO Labor'!$F$5="Y",1,0),"") | K11: =IFERROR(IF(OR(N(B11)=0,N(G11)=0),"",ROUNDUP(N(B11)/2,0)*N(G11)*N('TPO Labor'!$F$7))*IF('TPO Labor'!$F$5="Y",1,0),"") | L11: =IFERROR((N(J11)+N(K11))*N('TPO Labor'!$F$8),"") | M11: =IFERROR(N(H11)+N(J11)+N(K11)+N(L11),"")
A12: Field details | C12: =IFERROR(N(B12)*N('TPO Labor'!$B$7),"") | D12: =IFERROR('Material Takeoff'!G6,"") | E12: sq | G12: =IFERROR(IF(N(F12)=0,"",N(D12)/N(F12)),"") | H12: =IFERROR(IF(OR(N(G12)=0,N(C12)=0),"",N(G12)*N(C12)),"") | I12: =IFERROR(IF(N(D12)=0,"",N(H12)/N(D12)),"") | J12: =IFERROR(IF(OR(N(B12)=0,N(G12)=0),"",N(B12)*N(G12)*N('TPO Labor'!$F$6))*IF('TPO Labor'!$F$5="Y",1,0),"") | K12: =IFERROR(IF(OR(N(B12)=0,N(G12)=0),"",ROUNDUP(N(B12)/2,0)*N(G12)*N('TPO Labor'!$F$7))*IF('TPO Labor'!$F$5="Y",1,0),"") | L12: =IFERROR((N(J12)+N(K12))*N('TPO Labor'!$F$8),"") | M12: =IFERROR(N(H12)+N(J12)+N(K12)+N(L12),"")
A13: Walls | C13: =IFERROR(N(B13)*N('TPO Labor'!$B$7),"") | D13: =IFERROR('Material Takeoff'!G8,"") | E13: sq | G13: =IFERROR(IF(N(F13)=0,"",N(D13)/N(F13)),"") | H13: =IFERROR(IF(OR(N(G13)=0,N(C13)=0),"",N(G13)*N(C13)),"") | I13: =IFERROR(IF(N(D13)=0,"",N(H13)/N(D13)),"") | J13: =IFERROR(IF(OR(N(B13)=0,N(G13)=0),"",N(B13)*N(G13)*N('TPO Labor'!$F$6))*IF('TPO Labor'!$F$5="Y",1,0),"") | K13: =IFERROR(IF(OR(N(B13)=0,N(G13)=0),"",ROUNDUP(N(B13)/2,0)*N(G13)*N('TPO Labor'!$F$7))*IF('TPO Labor'!$F$5="Y",1,0),"") | L13: =IFERROR((N(J13)+N(K13))*N('TPO Labor'!$F$8),"") | M13: =IFERROR(N(H13)+N(J13)+N(K13)+N(L13),"")
A14: Wall details | C14: =IFERROR(N(B14)*N('TPO Labor'!$B$7),"") | D14: =IFERROR('Material Takeoff'!G8,"") | E14: sq | G14: =IFERROR(IF(N(F14)=0,"",N(D14)/N(F14)),"") | H14: =IFERROR(IF(OR(N(G14)=0,N(C14)=0),"",N(G14)*N(C14)),"") | I14: =IFERROR(IF(N(D14)=0,"",N(H14)/N(D14)),"") | J14: =IFERROR(IF(OR(N(B14)=0,N(G14)=0),"",N(B14)*N(G14)*N('TPO Labor'!$F$6))*IF('TPO Labor'!$F$5="Y",1,0),"") | K14: =IFERROR(IF(OR(N(B14)=0,N(G14)=0),"",ROUNDUP(N(B14)/2,0)*N(G14)*N('TPO Labor'!$F$7))*IF('TPO Labor'!$F$5="Y",1,0),"") | L14: =IFERROR((N(J14)+N(K14))*N('TPO Labor'!$F$8),"") | M14: =IFERROR(N(H14)+N(J14)+N(K14)+N(L14),"")
A15: Curb flashing | D15: =IFERROR('Material Takeoff'!B137,"") | E15: LF | H15: =IFERROR(IF(OR(N(D15)=0,N(I15)=0),"",N(D15)*N(I15)),"") | M15: =IFERROR(N(H15),"")
A16: Pitch pans | D16: =IFERROR('Material Takeoff'!B133,"") | E16: ea | H16: =IFERROR(IF(OR(N(D16)=0,N(I16)=0),"",N(D16)*N(I16)),"") | M16: =IFERROR(N(H16),"")
A17: Pipe boots | D17: =IFERROR('Material Takeoff'!B134,"") | E17: ea | H17: =IFERROR(IF(OR(N(D17)=0,N(I17)=0),"",N(D17)*N(I17)),"") | M17: =IFERROR(N(H17),"")
A18: TPO LABOR — PAGE TOTAL | H18: =IFERROR(SUM(H11:H17),"") | I18: =IFERROR(IF((N('Material Takeoff'!G6)+N('Material Takeoff'!G8))=0,"",N(H18)/(N('Material Takeoff'!G6)+N('Material Takeoff'!G8))),"") | J18: =IFERROR(SUM(J11:J17),"") | K18: =IFERROR(SUM(K11:K17),"") | L18: =IFERROR(SUM(L11:L17),"") | M18: =IFERROR(SUM(M11:M17),"")
A19: Yellow = labor. Green = per diem. Blue = hotel. Orange = travel markup. Purple = what that sub gets paid, all in. Every colour adds straight down its own column.

Sheet Metal Labor
A1: METAL LABOR — MECHANICALLY ATTACHED TPO · TEAR-OFF
A2: One row per trade. Same columns as the TPO page. Rates are set on the TPO Labor page. This page totals METAL ONLY.
A4: TRADE | B4: MEN | C4: CREW $/DAY | D4: QTY | E4: UNIT | F4: PER DAY | G4: DAYS | H4: LABOR $ | I4: $ PER UNIT | J4: PER DIEM | K4: HOTEL | L4: TRAVEL MKUP | M4: TRADE TOTAL
A5: Gravel stop | C5: =IFERROR(N(B5)*N('TPO Labor'!$B$7),"") | D5: =IFERROR('Material Takeoff'!B120,"") | E5: LF | G5: =IFERROR(IF(N(F5)=0,"",N(D5)/N(F5)),"") | H5: =IFERROR(IF(OR(N(G5)=0,N(C5)=0),"",N(G5)*N(C5)),"") | I5: =IFERROR(IF(N(D5)=0,"",N(H5)/N(D5)),"") | J5: =IFERROR(IF(OR(N(B5)=0,N(G5)=0),"",N(B5)*N(G5)*N('TPO Labor'!$F$6))*IF('TPO Labor'!$F$5="Y",1,0),"") | K5: =IFERROR(IF(OR(N(B5)=0,N(G5)=0),"",ROUNDUP(N(B5)/2,0)*N(G5)*N('TPO Labor'!$F$7))*IF('TPO Labor'!$F$5="Y",1,0),"") | L5: =IFERROR((N(J5)+N(K5))*N('TPO Labor'!$F$8),"") | M5: =IFERROR(N(H5)+N(J5)+N(K5)+N(L5),"")
A6: Gravel stop cleat | C6: =IFERROR(N(B6)*N('TPO Labor'!$B$7),"") | D6: =IFERROR(Takeoff!B103,"") | E6: LF | G6: =IFERROR(IF(N(F6)=0,"",N(D6)/N(F6)),"") | H6: =IFERROR(IF(OR(N(G6)=0,N(C6)=0),"",N(G6)*N(C6)),"") | I6: =IFERROR(IF(N(D6)=0,"",N(H6)/N(D6)),"") | J6: =IFERROR(IF(OR(N(B6)=0,N(G6)=0),"",N(B6)*N(G6)*N('TPO Labor'!$F$6))*IF('TPO Labor'!$F$5="Y",1,0),"") | K6: =IFERROR(IF(OR(N(B6)=0,N(G6)=0),"",ROUNDUP(N(B6)/2,0)*N(G6)*N('TPO Labor'!$F$7))*IF('TPO Labor'!$F$5="Y",1,0),"") | L6: =IFERROR((N(J6)+N(K6))*N('TPO Labor'!$F$8),"") | M6: =IFERROR(N(H6)+N(J6)+N(K6)+N(L6),"")
A7: Downspouts | C7: =IFERROR(N(B7)*N('TPO Labor'!$B$7),"") | D7: =IFERROR('Material Takeoff'!B122,"") | E7: LF | G7: =IFERROR(IF(N(F7)=0,"",N(D7)/N(F7)),"") | H7: =IFERROR(IF(OR(N(G7)=0,N(C7)=0),"",N(G7)*N(C7)),"") | I7: =IFERROR(IF(N(D7)=0,"",N(H7)/N(D7)),"") | J7: =IFERROR(IF(OR(N(B7)=0,N(G7)=0),"",N(B7)*N(G7)*N('TPO Labor'!$F$6))*IF('TPO Labor'!$F$5="Y",1,0),"") | K7: =IFERROR(IF(OR(N(B7)=0,N(G7)=0),"",ROUNDUP(N(B7)/2,0)*N(G7)*N('TPO Labor'!$F$7))*IF('TPO Labor'!$F$5="Y",1,0),"") | L7: =IFERROR((N(J7)+N(K7))*N('TPO Labor'!$F$8),"") | M7: =IFERROR(N(H7)+N(J7)+N(K7)+N(L7),"")
A8: 2 x 8 nailer | C8: =IFERROR(N(B8)*N('TPO Labor'!$B$7),"") | D8: =IFERROR('Material Takeoff'!G166,"") | E8: LF | G8: =IFERROR(IF(N(F8)=0,"",N(D8)/N(F8)),"") | H8: =IFERROR(IF(OR(N(G8)=0,N(C8)=0),"",N(G8)*N(C8)),"") | I8: =IFERROR(IF(N(D8)=0,"",N(H8)/N(D8)),"") | J8: =IFERROR(IF(OR(N(B8)=0,N(G8)=0),"",N(B8)*N(G8)*N('TPO Labor'!$F$6))*IF('TPO Labor'!$F$5="Y",1,0),"") | K8: =IFERROR(IF(OR(N(B8)=0,N(G8)=0),"",ROUNDUP(N(B8)/2,0)*N(G8)*N('TPO Labor'!$F$7))*IF('TPO Labor'!$F$5="Y",1,0),"") | L8: =IFERROR((N(J8)+N(K8))*N('TPO Labor'!$F$8),"") | M8: =IFERROR(N(H8)+N(J8)+N(K8)+N(L8),"")
A9: Shop fabrication — flat metal | D9: =IFERROR(Takeoff!G106,"") | E9: sheet | H9: =IFERROR(IF(OR(N(D9)=0,N(I9)=0),"",N(D9)*N(I9)),"") | M9: =IFERROR(N(H9),"")
A10: 7/16" OSB install | D10: =IFERROR('Material Takeoff'!G167,"") | E10: sheet | H10: =IFERROR(IF(OR(N(D10)=0,N(I10)=0),"",N(D10)*N(I10)),"") | M10: =IFERROR(N(H10),"")
A11: METAL LABOR — PAGE TOTAL | H11: =IFERROR(SUM(H5:H10),"") | J11: =IFERROR(SUM(J5:J10),"") | K11: =IFERROR(SUM(K5:K10),"") | L11: =IFERROR(SUM(L5:L10),"") | M11: =IFERROR(SUM(M5:M10),"")
A12: Shop fabrication and OSB carry no per diem and no hotel — that work happens at the shop, not in Houston.

Sheet Totals
A1: TOTALS — MECHANICALLY ATTACHED TPO
A2: Materials. Labor. Travel. Everything else. That is the whole page.
A4: MATERIALS
A5: Materials w/ tax | B5: =IFERROR('Material Order'!F134,"") | C5: every material on the Material Order page, tax included
A6: Material markup % | C6: VARIABLE — set it on THIS job. Materials carry no markup until it is answered.
A7: Material markup | B7: =IFERROR((N('Material Order'!F134)-(N('Material Order'!F104)+N('Material Order'!F106))*(1+N('Material Order'!E133)))*N(B6),"") | C7: scuppers and collector heads are all-in — they do not get marked up
A9: LABOR
A10: TPO labor | B10: =IFERROR('TPO Labor'!H18,"") | C10: TPO Labor page, LABOR $ column total
A11: Metal labor | B11: =IFERROR('Metal Labor'!H11,"") | C11: Metal Labor page, LABOR $ column total
A13: TRAVEL — two crews, kept apart
A14: TPO crew — per diem | B14: =IFERROR('TPO Labor'!J18,"") | C14: green column, TPO Labor page
A15: TPO crew — hotels | B15: =IFERROR('TPO Labor'!K18,"") | C15: blue column, TPO Labor page
A16: TPO crew — travel markup | B16: =IFERROR('TPO Labor'!L18,"") | C16: orange column, TPO Labor page
A17: Metal crew — per diem | B17: =IFERROR('Metal Labor'!J11,"") | C17: green column, Metal Labor page
A18: Metal crew — hotels | B18: =IFERROR('Metal Labor'!K11,"") | C18: blue column, Metal Labor page
A19: Metal crew — travel markup | B19: =IFERROR('Metal Labor'!L11,"") | C19: orange column, Metal Labor page
A20: ="All six read zero unless OUT OF TOWN on the TPO Labor page is set to Y. It is "&IF('TPO Labor'!$B$8="Y","Y — travel is ON.","N — travel is OFF.")
A22: BEFORE THIS GOES OUT
A23: Warranty / NDL
A24: Special insurance
A25: Tool purchase / rental
A26: Bonds (P&P / performance)
A27: Skytrack rental
A28: Dumpsters | B28: =IFERROR(ROUNDUP(N(B33)/10,0)*700,"") | C28: $700 a dumpster, one load every 10 squares
A29: Misc markup % | C29: VARIABLE — set it on THIS job. Applies to insurance, tools, bonds, Skytrack, dumpsters. Nothing marks up until it is answered.
A30: Misc markup | B30: =IFERROR((N(B24)+N(B25)+N(B26)+N(B27)+N(B28))*N(B29),"")
A32: TOTAL BID | B32: =IFERROR(N(B5)+N(B7)+N(B10)+N(B11)+N(B14)+N(B15)+N(B16)+N(B17)+N(B18)+N(B19)+N(B23)+N(B24)+N(B25)+N(B26)+N(B27)+N(B28)+N(B30),"")
A33: Total squares | B33: =IFERROR('Material Takeoff'!G9,"")
A34: PRICE PER SQUARE | B34: =IFERROR(IF(N(B33)=0,"",N(B32)/N(B33)),"")
A35: Every line above is one number from one place. Nothing on this page is calculated twice.

Sheet Bid Products
A1: BID PRODUCTS — what this job actually buys
A2: One row per Material Order line. Every product below is the exact line off Blake Babcock's sheet (Specialized Building Materials, 8/25/26) — item number, pack size, price. Anything with no item number is not on that sheet.
A3: Material Order line | B3: Product (from the applied manufacturer price sheet) | C3: Unit | D3: PRICE | E3: Note | F3: How the price is figured
A4: TPO field membrane 10' | B4: 31012 GAF TPO .060 Wht 10'X100' · 10 SQ/ROLL | C4: roll | D4: 710 | F4: $0.710/sf x 1,000 sf (10 ft x 100 ft roll) = $710.00 a roll
A5: TPO field membrane 5' | B5: 31014 GAF TPO .060 Wht 5'X100' · 5 SQ/ROLL | C5: roll | D5: 355 | F5: $0.710/sf x 500 sf (5 ft x 100 ft roll) = $355.00 a roll
A6: Polyiso — field of the roof | B6: 12004 Insulation ISO 1.6" (LTTR 9.4) 4x8 · 51 BDFT/EA | C6: board | D6: 21.76 | E6: $68.00/sq on the sheet | F6: 4x8 = 32 sf. 32 sf x 1.6 in = 51.2 board-feet. 51.2 x $0.425/bdft = $21.76 a board
A7: Crickets — Scuppers / Drains · Q board | B7: 11000 ISO Taper Panel Q (0.5"-2.5") 4x4 · 24 BDFT/EA | C7: board | D7: 14.28 | E7: $89.25/sq on the sheet | F7: Q panel is 0.5-2.5 in, so 1.5 in average. 4x4 = 16 sf. 16 x 1.5 = 24 board-feet. 24 x $0.595/bdft = $14.28 a board
A8: Crickets — Units · Q board | B8: 11000 ISO Taper Panel Q (0.5"-2.5") 4x4 · 24 BDFT/EA | C8: board | D8: 14.28 | E8: $89.25/sq on the sheet | F8: Q panel is 0.5-2.5 in, so 1.5 in average. 4x4 = 16 sf. 16 x 1.5 = 24 board-feet. 24 x $0.595/bdft = $14.28 a board
A9: ISO plates | B9: 20000 GAF Drill-Tec Stnd Flat Steel Galv Insul Plate 3" (#4181B) · 500/EA | C9: box | D9: 118.96 | F9: $118.96 a box of 500 = $0.238 a plate
A10: Seam plates | B10: 20003 GAF Drill-Tec 2-3/8" EGX-FM Steel Plate, Barbed · 1000/EA | C10: box | D10: 376.44 | E10: sheet says 2-3/8", not the 2-3/4" in the crosswalk | F10: $376.44 a box of 1,000 = $0.376 a plate
A11: Insulation fasteners #12 | B11: 20011 GAF Drill-Tec 5" #12 Fastener · #3 Phillips · 1000/EA | C11: box | D11: 270.32 | E11: IT IS on Blake's sheet. Claude's earlier "#12 HD" was invented — this is the real line. | F11: $270.32 a box of 1,000 = $0.270 a screw
A12: Seam fasteners #15 — 5" | B12: 20037 GAF Drill-Tec 5" #15 Washer Head Fastener · #3 Phillips · 500/EA | C12: box | D12: 192.69 | E12: PACK IS 500, not 1000. The sheet was built on 1000 — corrected. | F12: $192.69 a box of 500 = $0.385 a screw. PACK IS 500, not 1,000.
A13: Bonding adhesive | B13: 41022 GAF TPO #1121 Solvent Based Bonding Adhesive 5GL | C13: pail | D13: 149.5 | F13: $149.50 a 5-gallon pail
A14: Rollers | B14: shop supply | C14: ea | D14: 5 | E14: shop supply — not on Blake's sheet | F14: shop supply — $5.00 each
A15: Cages | B15: shop supply | C15: ea | D15: 5 | E15: shop supply — not on Blake's sheet | F15: shop supply — $5.00 each
A16: Sticks | B16: shop supply | C16: ea | D16: 5 | E16: shop supply — not on Blake's sheet | F16: shop supply — $5.00 each
A17: Unsupported flashing | B17: 41044 GAF TPO UN-55 Flexible Detail Memb. Wht 24"X50' · 50 LF/ROLL | C17: roll | D17: 435.5 | F17: $435.50 a roll. 24 in x 50 ft = 100 sf a roll = $4.36/sf
A18: TPO T-joints | B18: 41037 GAF TPO Flexible T-Joint Patch White 4"X4" · 100/EA | C18: box | D18: 99 | F18: $99.00 a box of 100 = $0.99 a patch
A19: TPO corners | B19: 41028 GAF TPO Flexible Fluted Outside Corner 8" Diameter · 20 EA/CTN | C19: ea | D19: 13.51 | E19: PICK ONE: 41045 Universal Corners 4"x4" is $12.69 — which corner do you run? | F19: $13.51 each. Comes 20 to a carton = $270.20 a carton, but it is bought by the piece.
A20: TPO molded pipe boots | B20: 41047 GAF TPO Vent Boots White 1"-6" · 6 EA/CTN | C20: ea | D20: 44.5 | F20: $44.50 each. 6 to a carton.
A21: Pitch pockets | B21: 41020 GAF Split Pourable Sealant Pocket White · 6 EA/CTN | C21: ea | D21: 59.5 | F21: $59.50 each. 6 to a carton.
A22: Pourable sealer | B22: 41015 GAF 1-Part Pourable Sealant White · 4 KT/CTN | C22: kit | D22: 85.8 | E22: was $85.50 — sheet says $85.80 | F22: $85.80 a kit. 4 kits to a carton.
A23: TPO cover tape | B23: 41023 GAF TPO Dbl Cover Tape Wht 6"X100' · 100 LF/ROLL | C23: roll | D23: 356.5 | E23: PICK ONE: 41033 Primerless Dbl $356.50 · 41024 Heatweld $388.50 · 41025 60M Flashing Strip 8"x100 $283.19 | F23: $356.50 a roll. 6 in x 100 ft = 100 LF a roll = $3.565/LF
A24: Primer | B24: IKO / Innovi TPO Tape Primer 3Gl (6/Ctn) | C24: can | D24: 164.75 | E24: LAW — 3-GALLON ONLY. Never the 1-gallon. Blake sells the IKO 3G; that is the line, every time. | F24: IKO / Innovi TPO Tape Primer 3 GALLON, 6 to a carton. $164.75 a jug.
A25: Brushes | B25: shop supply | C25: ea | D25: 5 | E25: shop supply — not on Blake's sheet | F25: shop supply — $5.00 each
A26: TPO cut-edge sealant | B26: 41027 GAF TPO Cut Edge Sealant Wht Pint · 12 EA/CTN | C26: tube | D26: 26.65 | F26: $26.65 a pint. 12 to a carton.
A27: TPO LVOC all-purpose | B27: 41017 GAF FlexSeal Caulk Grade (Red Label) · 20-10OZ/CTN | C27: can | D27: 14.59 | F27: $14.59 a tube. 20 tubes of 10 oz to a carton.
A28: Water block | B28: 41016 GAF Evrg Water Block Mastic 10.3oz · 25 EA/CTN | C28: tube | D28: 8.9 | F28: $8.90 a tube of 10.3 oz. 25 to a carton.
A29: TPO cleaner 5g | B29: Carlisle / QXO TPO seam cleaner 5-GALLON | C29: can | D29: 150 | E29: ESTIMATE — Adam gave $150 to stand in until the QXO invoice with the 5-gal cleaner is found. Not a quoted price. | F29: $150.00 a 5-gallon can
A30: Rags | B30: shop supply — box | C30: box | D30: 40 | E30: shop supply — not on Blake's sheet | F30: shop supply — $40.00 a box
A31: Hose clamps | B31: shop supply — box | C31: roll | D31: 100 | E31: shop supply — not on Blake's sheet | F31: shop supply — $100.00 a roll
A32: Roof hatch | B32: TRI-BUILT Roof Hatch Galvanized 36 x 30 · SKU TRIRHG3630 (TBG3036) · 1 pc | C32: ea | D32: 850 | E32: QXO invoice VG76853, 9/1/26, PO "FATE 20K ROOF HATCH" — 1 pc @ $850.00 + $70.13 tax = $920.13. Price, product and qty all checked AS 9/7/26.
A33: Safety ladder-up post | B33: NA | C33: ea | E33: NA — no safety ladder-up post on this job. No product, no price.
A34: Backer rod | B34: Backer rod — 20 ft bag | C34: bag | D34: 4 | E34: ESTIMATE — $4 a bag, from the earlier pricing notes ("~$4/20ft"). Never tied to an invoice. Not on Blake's sheet.
A35: Railing / guardrail set | B35: NA | C35: ea | E35: NA — no railing / guardrail set on this job. No product, no price.
A36: Walkpad | B36: 41048 GAF TPO Walkway Roll — Gray 34.25" x 50'5" · 50 LF/ROLL | C36: roll | D36: 665 | E36: Blake / SBM 8/25/26 sheet, page 31, item 41048 — $665.00 per 50 LF roll.
A37: Coping metal | B37: NA | C37: sheet | E37: NA — no coping metal on this job. No product, no price.
A38: Coping cleat | B38: NA | C38: sheet | E38: NA — no coping cleat on this job. No product, no price.
A39: Gravel stop metal | B39: 24g Kynar flat 4 x 10 | C39: sheet | D39: 80 | E39: QXO / metal supplier — not on Blake's sheet | F39: $80.00 a 4 ft x 10 ft sheet of 24g Kynar flat
A40: Gravel stop cleat | B40: MAJ G90 20GA GALVANIZED 4 x 10 — QXO MAJ20G90 | C40: sheet | D40: 58.5 | E40: QXO MAJ20G90 — not on Blake's sheet | F40: $58.50 a 4 ft x 10 ft sheet of 20g galv. QXO MAJ20G90, 7/22/26 invoice UZ87925.
...

Sheet Plan Reference
A1: PLAN REFERENCE — job:
A2: Where the wall numbers on the Takeoff page came from. Reference only — nothing here feeds a calculation. Read every job off its own plans.
A4: WALL SECTIONS — sheet numbers and the scale they are drawn at
A5: Condition | B5: T.O. parapet | C5: Parapet above deck | D5: Cap width | E5: Sections
A11: Check the printed cap dimensions against the scale before trusting any of it. A parapet FRAMING height is not the height above the roof deck.
A22: TERMINATION
A23: How every section terminates — write it here off this job's details.

Sheet Material Takeoff
A1: MATERIAL TAKEOFF — MECHANICALLY ATTACHED TPO
A2: PAGE TWO. Nothing is typed here except a FACTOR. Every driver reads live off the Takeoff page. Each line: DRIVER x/÷ FACTOR = RAW → QTY.
A4: 1 · SQUARES
A5: Item | B5: Driver | C5: Unit | E5: Where it comes from | G5: Squares
A6: Field squares | B6: =IFERROR(Takeoff!B20,"") | C6: sf | E6: Takeoff A · field squares | G6: =IFERROR(ROUNDUP(B6/100,0),"") | H6: sq
A8: Wall squares | B8: =IFERROR(Takeoff!H46,"") | C8: sf | E8: Takeoff C · total wall sq ft | G8: =IFERROR(ROUNDUP(B8/100,0),"") | H8: sq
A9: TOTAL SQUARES (field + walls) | E9: field squares + wall squares | G9: =IFERROR(N(G6)+N(G8),"") | H9: sq
A10: ="Field "&TEXT(G6,"0")&" sq · walls "&TEXT(G8,"0")&" sq · TOTAL "&TEXT(G9,"0")&" sq. Squares always round UP."
A12: 2 · INSULATION
A13: Item | B13: Driver | C13: Unit | D13: Factor | E13: What the factor means | F13: RAW | G13: Qty | H13: Pkg
A14: Polyiso — field of the roof | B14: =IFERROR(G6,"") | C14: sq | D14: 3 | E14: field squares x 3 | F14: =IFERROR(IF(OR(B14="",D14=""),"",B14*D14),"") | G14: =IFERROR(IF(F14="","",ROUNDUP(F14,0)),"") | H14: board
A17: "Squares x 3 = boards. Flat — no waste factor, because in the field those boards never seat like they did in the factory: an eighth of an inch between every one, cuts around everything, and a perimeter that is never snug to the wall. That IS the waste, and 3 covers it."
A19: 2b · Q BOARD — 2" tapered filler for the crickets
A20: "THE LAYOUT WINS. If the takeoff app drew this roof, its board count is the number — it lays the boards out one at a time and counts the leftovers. Only when there is no layout does the sheet fall back to cricket LF x 1.2 ÷ 4 ft board. 4″ and 2″ fill are two different boards off two different pallets and never get added together."
A21: Item | B21: Q board FROM THE LAYOUT | C21: Unit | D21: 2″ fill FROM THE LAYOUT | E21: Cricket LF (only if there is no layout) | F21: Fallback boards | G21: BOARDS USED | H21: Pkg | J21: Where the number came from
A22: Crickets — Units | C22: bd | F22: =IFERROR(IF(E22="","",ROUNDUP(E22*1.2/4,0)),"") | G22: =IFERROR(IF(B22<>"",B22,IF(F22<>"",F22,"")),"") | H22: board | I22: 52 units, one cricket per unit curb. 294.32 ft of leading edge on the layout. This scope can come out of the quote on its own. | J22: =IF(B22<>"","from the layout — the app counted the boards",IF(E22<>"","no layout, so LF x 1.2 ÷ 4","nothing to go on yet"))
A23: Crickets — Scuppers / Drains | C23: bd | F23: =IFERROR(IF(E23="","",ROUNDUP(E23*1.2/4,0)),"") | G23: =IFERROR(IF(B23<>"",B23,IF(F23<>"",F23,"")),"") | H23: board | I23: 7 crickets steering water to the scuppers and drains. 344.64 ft of leading edge on the layout. These have to be there. | J23: =IF(B23<>"","from the layout — the app counted the boards",IF(E23<>"","no layout, so LF x 1.2 ÷ 4","nothing to go on yet"))
A24: ="Units "&TEXT(N(G22),"0")&" Q board. Scuppers/Drains "&TEXT(N(G23),"0")&" Q board + "&TEXT(N(D23),"0")&" pieces of 2″ fill at 4 ft x 4 ft. "&IF(N(B22)+N(B23)>0,"Both taken off the drawn layout.","No layout — figured off cricket LF.")
A25: 3 · TPO MEMBRANE — 60-mil. 10 ft in the middle, 5 ft around the outside, 5 ft on the walls
A26: "A roll gives as many squares as it is feet wide — a 10 ft roll is 10 squares, a 5 ft roll is 5. Six inches of every roll is the selvage that gets lapped over, so a 5 ft roll loses 10% and a 10 ft roll only loses 5%. Cuts are on top of that."
A27: Item | B27: Driver | C27: Unit | D27: Cuts % | E27: Factor (1 + lap + cuts) | F27: RAW | G27: Qty | H27: Roll width (ft)
A28: Field membrane 10' (interior) | B28: =IFERROR(Takeoff!B129,"") | C28: sq | D28: 0.1 | E28: =IFERROR(IF(OR(D28="",H28=""),"",1+(0.5/H28)+D28),"") | F28: =IFERROR(IF(OR(B28="",E28="",H28=""),"",B28*E28/H28),"") | G28: =IFERROR(IF(F28="","",ROUNDUP(F28,0)),"") | H28: 10
A29: Field membrane 5' (perimeter) | B29: =IFERROR(Takeoff!B128,"") | C29: sq | D29: 0.1 | E29: =IFERROR(IF(OR(D29="",H29=""),"",1+(0.5/H29)+D29),"") | F29: =IFERROR(IF(OR(B29="",E29="",H29=""),"",B29*E29/H29),"") | G29: =IFERROR(IF(F29="","",ROUNDUP(F29,0)),"") | H29: 5
A30: Wall membrane 5' | B30: =IFERROR(G8,"") | C30: sq | D30: 0.15 | E30: =IFERROR(IF(OR(D30="",H30=""),"",1+(0.5/H30)+D30),"") | F30: =IFERROR(IF(OR(B30="",E30="",H30=""),"",B30*E30/H30),"") | G30: =IFERROR(IF(F30="","",ROUNDUP(F30,0)),"") | H30: 5
A31: ="Interior "&TEXT(N(B28),"0")&" sq x "&TEXT(E28,"0.00")&" ÷ 10 sq per roll = "&TEXT(N(G28),"0")&" rolls of 10 ft. Perimeter "&TEXT(N(B29),"0")&" sq x "&TEXT(E29,"0.00")&" ÷ 5 sq per roll = "&TEXT(N(G29),"0")&" rolls of 5 ft. Walls "&TEXT(N(B30),"0")&" sq x "&TEXT(E30,"0.00")&" ÷ 5 = "&TEXT(N(G30),"0")&" rolls."
A32: 4 · FASTENERS & SEAM PLATES
A33: "TWO SCREWS ON THIS ROOF, ONE LENGTH. The length falls out of the stack: insulation + the deck itself + a full inch through the bottom, rounded up to the next size. The gauges are a rule and do not move: the screw that holds the INSULATION down is a #12, the screw that holds a SEAM PLATE down is a #15."
A34: Item | B34: Value | C34: Unit | E34: How it is decided
A35: Fastener LENGTH (both screws) | B35: =IFERROR(ROUNDUP(N(Takeoff!B10)+N(Takeoff!B9)+IF(ISNUMBER(SEARCH("WOOD",UPPER(Takeoff!B8))),0.5,0)+1,0),"") | C35: in | E35: =IFERROR("insulation "&TEXT(N(Takeoff!B10),"0.0#")&"in + deck "&TEXT(N(Takeoff!B9)+IF(ISNUMBER(SEARCH("WOOD",UPPER(Takeoff!B8))),0.5,0),"0.0#")&"in + 1in through the bottom = "&TEXT(N(Takeoff!B10)+N(Takeoff!B9)+IF(ISNUMBER(SEARCH("WOOD",UPPER(Takeoff!B8))),0.5,0)+1,"0.0#")&"in, rounded up to "&TEXT(N(B35),"0")&"in. No cover board on this job.","")
A36: Insulation fastener GAUGE | B36: 12 | C36: gauge | E36: RULE. The screw that holds the insulation down is a #12. It does not change with the deck.
A37: Seam fastener GAUGE | B37: 15 | C37: gauge | E37: =IF(ISNUMBER(SEARCH("WOOD",UPPER(Takeoff!L38))),"RULE. Every seam plate takes a #15 — field, curbs, boots, pans. WOOD walls are the one exception: the wall and base-flashing plates take a 3in #14 into the wood.","RULE. Every seam plate takes a #15 — field, curbs, boots, pans, walls and base flashing. Walls are "&LOWER(Takeoff!L38)&", so nothing is screwed into the wall and there is no 3in #14 on this job.")
A38: ="Both screws are "&TEXT(N(B35),"0")&"in long. Insulation = #"&TEXT(N(B36),"0")&". Seam plates = #"&TEXT(N(B37),"0")&"."&IF(ISNUMBER(SEARCH("WOOD",UPPER(Takeoff!L38)))," Wood walls: the wall and base-flashing plates take a 3in #14 instead.","")
A40: Item | B40: Boards | C40: Unit | D40: Plates per board | E40: Plates per box | F40: RAW plates | G40: Boxes | H40: Pkg
A41: ISO plates | B41: =IFERROR(N(G14),"") | C41: board | D41: =IFERROR(Takeoff!B14,"") | E41: 500 | F41: =IFERROR(IF(OR(B41="",D41=""),"",B41*D41),"") | G41: =IFERROR(IF(OR(F41="",N(E41)=0),"",ROUNDUP(F41/E41,0)),"") | H41: box
A43: 4b · WALL FASTENING — 3" #14 + seam plate at 12" o.c., a seam every sheet width along the run
A44: "The run that gets fastened off is the WALL face. The cap is NOT in it — the membrane goes over the cap and terminates, it does not get a row up there. A seam lands every 5 ft along that run and the top one is not counted, because that is where it folds over."
A45: Rule | B45: Value | C45: Unit | E45: What it means
A46: Wall fastener row spacing (LAW — every 5 ft for wind uplift) | B46: 5 | C46: ft | E46: LAW, not a setting. A wall gets a row of fasteners every 5 ft up its height, for wind uplift. Run a 10 ft sheet on a wall and you still fasten fingers through its mid-point to keep the rows 5 ft apart. This does NOT follow the field sheet width.
A47: Cap is not part of the run | E47: the membrane runs over the cap and terminates — no fastener row up there
A48: Variance off the top | B48: 2 | C48: ft | E48: a row that lands inside this of the top is not worth putting in. 11 ft wall = 1 row, 12 ft wall = 2.
...

Sheet Lists
A1: SETUP LISTS — every dropdown on the Takeoff page reads its choices from the column under it
A2: HOW TO ADD A CHOICE THAT STICKS FOREVER: type it in the first empty cell under the heading. It is in that dropdown from then on, on this job and on every new bid started from this template. Nothing else to do. To retire a choice, delete the cell.
S3: Wood deck material | T3: Steel deck profile
A4: System | B4: Deck type | C4: Insulation thickness (in) | D4: Cover board thickness (in) | E4: Membrane thickness (mil) | F4: Field membrane sheet width (ft) | G4: ISO plates per board (ea) | H4: Wall fastener spacing (in) | I4: Base flashing spacing (in) | J4: Yes / No | K4: Field seam spacing (in) | L4: Construction type | M4: Decking | N4: Roof layer type | O4: How it is attached | P4: Insulation? (what board) | Q4: Gravel? | R4: Wall substrate
A5: ISO MA / TPO MA | B5: METAL | E5: 60 | F5: 5 | G5: 5 | H5: 6 | I5: 6 | J5: Y | K5: 6 | L5: Tear off | M5: Lightweight concrete over steel | N5: Modified bitumen | O5: Mechanically attached | P5: Recover board | Q5: Y | R5: Concrete | S5: OSB | T5: R panel
B6: WOOD | F6: 10 | H6: 12 | I6: 12 | J6: N | K6: 12 | L6: Recover | M6: Steel | N6: BUR | O6: Fully adhered | P6: ISO | Q6: N | R6: Wood | S6: Planks | T6: B deck
B7: CONCRETE | L7: Retrofit | M7: Wood | N7: TPO | O7: Mopped | P7: N/A | Q7: n/a | R7: Metal | S7: Plywood
B8: LWIC w/ metal pan | M8: Structural concrete | N8: PVC | O8: Torched
N9: Recover board + TPO | O9: Rhinobond
N10: Recover board + PVC | O10: Foamed
N11: N/A | O11: Loose laid / ballasted
O12: N/A
