Workbook

Sheet Totals
A1: TOTALS — BERRIDGE ZEE-LOCK (DOUBLE-LOCK)
A2: Labor and Materials pull LIVE from their tabs. Material markup is the only lever here.
A4: Material markup % | B4: 0.2
A6: Labor (from Labor tab) | B6: =Labor!E8
A7: Materials (from Material Order tab) | B7: ='Material Order'!E38
A8: Material markup (20%) | B8: =B7*B4
A9: TOTAL BID — clip boxes | B9: =B6+B7+B8
A10: TOTAL BID — continuous clip | B10: =B9+(('Bid (All-In Priced)'!I8*0.59)-'Bid (All-In Priced)'!G59)*1.0825*1.2
A11: Labor carries no markup (the ×2 in $500/man-day is its profit). Markup applies to materials only.
A12: ="Same bid both ways: clip boxes "&TEXT('Bid (All-In Priced)'!G59,"$#,##0.00")&" vs continuous "&TEXT('Bid (All-In Priced)'!I8*0.59,"$#,##0.00")&" material — difference "&TEXT(B10-B9,"$#,##0.00")&" on the total."

Sheet Bid
A1: SMS ROOFING — BERRIDGE ZEE-LOCK (DOUBLE-LOCK) • TEMPLATE — type the job into the blue cells
A2: Blue rows explain the line above with LIVE numbers. RED = raw/unrounded. Material pricing lives on the Material Order tab.
A4: 1 · PANEL TAKEOFF — quantity × length = linear feet (LF)
A5: ="A takeoff is counting what you install. Qty × Length = the LF that run needs. Sum all = total panel LF."
A6: Run | B6: Qty | C6: Length ft | I6: LF (Qty×Len)
A7: Panel LF (lump from takeoff) | B7: 1 | C7: 0 | I7: =B7*C7
A8: TOTAL PANEL LF | B8: =SUM(B7:B7) | I8: =SUM(I7:I7)
A9: ="All runs = "&B8&" panels = "&TEXT(I8,"#,##0.00")&" LF — drives coil, fab, labor, clips, vinyl. Add rows above as runs come in."
A11: 2 · PANEL SQUARES — LF into area (a ‘square’ = 100 sq ft)
A12: Panel coverage width (in) | F12: 16
A13: Panel SF = LF × (width ÷ 12) | F13: =I8*(F12/12)
A14: Panel SQUARES = SF ÷ 100 | F14: =F13/100
A15: ="Fab, labor, rivets price per square. "&TEXT(I8,"#,##0")&" LF × "&F12&"″÷12 = "&TEXT(F13,"#,##0")&" sf ÷100 = "&TEXT(F14,"0.00")&" sq."
A17: 3 · COIL — raw metal, full 1000′ (or 500′) rolls
A18: Item | B18: Need LF | C18: Coil LF | D18: Raw | E18: Coils
A19: Zee-Lock coil | B19: =I8 | C19: 500 | D19: =B19/C19 | E19: =ROUNDUP(D19,0)
A20: ="Need "&TEXT(I8,"#,##0")&" LF ÷ "&C19&"′/coil = "&TEXT(D19,"0.00")&" → buy "&E19&" × 500′ coils. (Pricing on Material Order tab.)"
A22: 4 · FLAT METAL — drip, hip/ridge, Z flash from 48″×10′ sheets
A23: ="Cut from 48″×10′ sheets. 48 ÷ stretch-out = strips across; ×10′ = LF/sheet. LF ÷ that = sheets (round UP)."
A24: Piece | B24: LF | C24: Stretch-out in | D24: LF/sheet | E24: Raw sheets | F24: Sheets
A25: D-style drip edge | B25: 0 | C25: 9.5 | D25: =FLOOR(48/C25,1)*10 | E25: =B25/D25 | F25: =ROUNDUP(E25,0)
A26: ="Drip: "&TEXT(B25,"#,##0")&" LF ÷ "&D25&" LF/sheet (48÷"&TEXT(C25,"0.0")&"″ = "&FLOOR(48/C25,1)&" strips ×10′) = "&TEXT(E25,"0.00")&" → "&F25&" sheets. (Sheet material + fab priced on other tabs.)"
A27: Drip edge cleat (only if face > 4″)
A28: Drip edge cleat: PENDING Adam — only when the drip face is over 4″. LF + stretch-out to confirm; out of every total until then.
A29: Rake-edge cap (req. Z) | B29: 0 | C29: 12 | D29: =FLOOR(48/C29,1)*10 | E29: =B29/D29 | F29: =ROUNDUP(E29,0)
A30: ="Rake-edge cap: "&TEXT(B29,"#,##0")&" LF ÷ "&D29&" LF/sheet (48÷"&TEXT(C29,"0.0")&"″ = "&FLOOR(48/C29,1)&" strips ×10′) = "&TEXT(E29,"0.00")&" → "&F29&" sheets. (Sheet material + fab priced on other tabs.)"
A31: Rake edge cleat (galv) | B31: =B29 | C31: 5 | D31: =FLOOR(48/C31,1)*10 | E31: =B31/D31 | F31: =ROUNDUP(E31,0)
A32: ="Rake edge cleat (follows rake-edge): "&TEXT(B31,"#,##0")&" LF ÷ "&D31&" LF/sheet (48÷"&TEXT(C31,"0.0")&"″ = "&FLOOR(48/C31,1)&" strips ×10′) = "&TEXT(E31,"0.00")&" → "&F31&" sheets. (Sheet material + fab priced on other tabs.)"
A33: (W) Valley | B33: 0 | C33: 24 | D33: =FLOOR(48/C33,1)*10 | E33: =B33/D33 | F33: =ROUNDUP(E33,0)
A34: ="(W) Valley: "&TEXT(B33,"#,##0")&" LF ÷ "&D33&" LF/sheet (48÷"&TEXT(C33,"0.0")&"″ = "&FLOOR(48/C33,1)&" strips ×10′) = "&TEXT(E33,"0.00")&" → "&F33&" sheets. (Sheet material + fab priced on other tabs.)"
A35: (W) Valley cleat (both sides ×2) | B35: =B33*2 | C35: 3 | D35: =FLOOR(48/C35,1)*10 | E35: =B35/D35 | F35: =ROUNDUP(E35,0)
A36: ="(W) Valley cleat (valley ×2 sides): "&TEXT(B35,"#,##0")&" LF ÷ "&D35&" LF/sheet (48÷"&TEXT(C35,"0.0")&"″ = "&FLOOR(48/C35,1)&" strips ×10′) = "&TEXT(E35,"0.00")&" → "&F35&" sheets. (Sheet material + fab priced on other tabs.)"
A37: Hip/Ridge cap (req. Z ×2 sides) | B37: 0 | C37: 16 | D37: =FLOOR(48/C37,1)*10 | E37: =B37/D37 | F37: =ROUNDUP(E37,0)
A38: ="Hip/Ridge: "&TEXT(B37,"#,##0")&" LF ÷ "&D37&" LF/sheet (48÷"&TEXT(C37,"0.0")&"″ = "&FLOOR(48/C37,1)&" strips ×10′) = "&TEXT(E37,"0.00")&" → "&F37&" sheets. (Sheet material + fab priced on other tabs.)"
A39: Rake wall (req. Z + counterflashing) | B39: 0 | C39: 12 | D39: =FLOOR(48/C39,1)*10 | E39: =B39/D39 | F39: =ROUNDUP(E39,0)
A40: ="Rake wall: "&TEXT(B39,"#,##0")&" LF ÷ "&D39&" LF/sheet (48÷"&TEXT(C39,"0.0")&"″ = "&FLOOR(48/C39,1)&" strips ×10′) = "&TEXT(E39,"0.00")&" → "&F39&" sheets. (Sheet material + fab priced on other tabs.)"
A41: Head wall (req. Z + counterflashing)
A42: Head wall: none on TEMPLATE — sample/checklist row (works like rake wall: Z + counterflash). Fill LF + SO when a job has one.
A43: Curb — L flash (req. term-bar CF) | B43: 0 | C43: 16 | D43: =FLOOR(48/C43,1)*10 | E43: =B43/D43 | F43: =ROUNDUP(E43,0)
A44: ="Curb L flash: "&TEXT(B43,"#,##0")&" LF ÷ "&D43&" LF/sheet (48÷"&TEXT(C43,"0.0")&"″ = "&FLOOR(48/C43,1)&" strips ×10′) = "&TEXT(E43,"0.00")&" → "&F43&" sheets. (Sheet material + fab priced on other tabs.)"
...

Sheet Material Order
A1: MATERIAL ORDER — BERRIDGE ZEE-LOCK (DOUBLE-LOCK)
A2: Quantities pull LIVE from the bid. Send the PURCHASED block to your supplier; the fab line is in-house.
A4: PURCHASED MATERIALS (send to supplier)
A5: Item | B5: Qty | C5: Unit | D5: Unit $ | E5: Line Total
A6: Zee-Lock coil (500′) | B6: ='Bid (All-In Priced)'!E19 | C6: coil | D6: =500*(20.875/12)*1.82 | E6: =B6*D6
A7: Flat sheet — D-style drip edge | B7: ='Bid (All-In Priced)'!F25 | C7: sheet | D7: =IF(N(B7)=0,"-",80) | E7: =IF(N(B7)=0,"-",B7*D7)
A8: Galv sheet — Drip edge cleat (PENDING) | B8: ='Bid (All-In Priced)'!F27 | C8: sheet | D8: =IF(N(B8)=0,"-",60) | E8: =IF(N(B8)=0,"-",B8*D8)
A9: Flat sheet — Rake-edge cap | B9: ='Bid (All-In Priced)'!F29 | C9: sheet | D9: =IF(N(B9)=0,"-",80) | E9: =IF(N(B9)=0,"-",B9*D9)
A10: Galv sheet — Rake edge cleat | B10: ='Bid (All-In Priced)'!F31 | C10: sheet | D10: =IF(N(B10)=0,"-",60) | E10: =IF(N(B10)=0,"-",B10*D10)
A11: Flat sheet — (W) Valley | B11: ='Bid (All-In Priced)'!F33 | C11: sheet | D11: =IF(N(B11)=0,"-",80) | E11: =IF(N(B11)=0,"-",B11*D11)
A12: Galv sheet — (W) Valley cleat | B12: ='Bid (All-In Priced)'!F35 | C12: sheet | D12: =IF(N(B12)=0,"-",60) | E12: =IF(N(B12)=0,"-",B12*D12)
A13: Flat sheet — Hip/Ridge cap | B13: ='Bid (All-In Priced)'!F37 | C13: sheet | D13: =IF(N(B13)=0,"-",80) | E13: =IF(N(B13)=0,"-",B13*D13)
A14: Flat sheet — Rake wall | B14: ='Bid (All-In Priced)'!F39 | C14: sheet | D14: =IF(N(B14)=0,"-",80) | E14: =IF(N(B14)=0,"-",B14*D14)
A15: Flat sheet — Head wall (sample) | B15: ='Bid (All-In Priced)'!F41 | C15: sheet | D15: =IF(N(B15)=0,"-",80) | E15: =IF(N(B15)=0,"-",B15*D15)
A16: Flat sheet — Curb L flash | B16: ='Bid (All-In Priced)'!F43 | C16: sheet | D16: =IF(N(B16)=0,"-",80) | E16: =IF(N(B16)=0,"-",B16*D16)
A17: Berridge Die-Formed Zee-Closure (710′ ÷ 16″) | B17: =ROUNDUP('Bid (All-In Priced)'!B45/(16/12),0) | C17: pc | D17: 1.99 | E17: =B17*D17
A18: Flat sheet — Counterflash | B18: ='Bid (All-In Priced)'!F47 | C18: sheet | D18: =IF(N(B18)=0,"-",80) | E18: =IF(N(B18)=0,"-",B18*D18)
A19: Flat sheet — Counterflash (term bar) | B19: ='Bid (All-In Priced)'!F49 | C19: sheet | D19: =IF(N(B19)=0,"-",80) | E19: =IF(N(B19)=0,"-",B19*D19)
A20: Caulk | B20: ='Bid (All-In Priced)'!D55 | C20: tube | D20: =IF(N(B20)=0,"-",10) | E20: =IF(N(B20)=0,"-",B20*D20)
A21: Rivets | B21: ='Bid (All-In Priced)'!D57 | C21: box | D21: =IF(N(B21)=0,"-",50) | E21: =IF(N(B21)=0,"-",B21*D21)
A22: Berridge Zee-Lock Clip 2-1/6" (300/box) | B22: ='Bid (All-In Priced)'!D59 | C22: box | D22: =IF(N(B22)=0,"-",174) | E22: =IF(N(B22)=0,"-",B22*D22)
A23: Vinyl — NONE on double-lock | B23: ='Bid (All-In Priced)'!D61 | C23: roll | D23: =IF(N(B23)=0,"-",392) | E23: =IF(N(B23)=0,"-",B23*D23)
A24: Screws (250/bag) | B24: ='Bid (All-In Priced)'!D63 | C24: bag | D24: =IF(N(B24)=0,"-",20) | E24: =IF(N(B24)=0,"-",B24*D24)
A25: Washer-head screws (250/bag) | B25: ='Bid (All-In Priced)'!D65 | C25: bag | D25: =IF(N(B25)=0,"-",20) | E25: =IF(N(B25)=0,"-",B25*D25)
A26: Hi-Temp Ice & Water | B26: ='Bid (All-In Priced)'!D76 | C26: roll | D26: =IF(N(B26)=0,"-",120) | E26: =IF(N(B26)=0,"-",B26*D26)
A27: Plastic cap nails | B27: ='Bid (All-In Priced)'!D78 | C27: box | D27: =IF(N(B27)=0,"-",25) | E27: =IF(N(B27)=0,"-",B27*D27)
A28: Delivery — standing seam (×2 trips) | B28: 2 | C28: trip | D28: 200 | E28: =B28*D28
A29: SP-21 panel machine rental (thru supply house) | B29: 2 | C29: week | D29: 1400 | E29: =B29*D29
A30: Purchased subtotal | E30: =SUM(E6:E29)
A32: IN-HOUSE (not ordered — a material-side cost in the bid)
A33: Item | B33: Qty | C33: Unit | D33: Unit $ | E33: Line Total
A34: Panel roll-form fabrication | B34: ='Bid (All-In Priced)'!F14 | C34: sq | D34: 40 | E34: =B34*D34
A36: MATERIAL SUBTOTAL (purchased + fab) | E36: =E30+E34
A37: Sales tax (8.25%) | E37: =E36*0.0825
A38: MATERIAL TOTAL (w/ tax) | E38: =E36+E37
A40: Blue = editable unit price. Qty is live from the bid. ‘Material total (w/tax)’ feeds both bid tabs.

Sheet Labor
A1: LABOR — BERRIDGE ZEE-LOCK (DOUBLE-LOCK)
A2: Qty pulls LIVE from the bid. No tax on labor (new con). The ×2 inside $500/man-day IS the labor profit.
A4: Line | B4: Qty | C4: Unit | D4: Rate | E4: Total
A5: Panel install (incl. ALL flat-metal install) | B5: ='Bid (All-In Priced)'!F14 | C5: sq | D5: =INDEX($D$14:$D$25,MATCH('Bid (All-In Priced)'!F71,$A$14:$A$25,0)) | E5: =B5*D5
A6: Ice & Water install | B6: ='Bid (All-In Priced)'!D77 | C6: sq | D6: =INDEX($C$14:$C$25,MATCH('Bid (All-In Priced)'!F71,$A$14:$A$25,0)) | E6: =B6*D6
A7: Flat-metal shop fab (all pieces) | B7: ='Bid (All-In Priced)'!F25+'Bid (All-In Priced)'!F29+'Bid (All-In Priced)'!F31+'Bid (All-In Priced)'!F33+'Bid (All-In Priced)'!F35+'Bid (All-In Priced)'!F37+'Bid (All-In Priced)'!F39+'Bid (All-In Priced)'!F43+'Bid (All-In Priced)'!F47+'Bid (All-In Priced)'!F49 | C7: sheet | D7: 40 | E7: =B7*D7
A8: LABOR TOTAL (no tax) | E8: =SUM(E5:E7)
A9: Blue = editable rate (charts below). Panel + I&W rates follow pitch automatically. 'Labor total' feeds the bid.
A10: Blue = editable rate. Qty live from bid. $250/sq covers panels AND all flat-metal field install. ‘Labor total’ feeds the bid.
A12: LABOR RATES BY PITCH ($/sq)
A13: Pitch | B13: Felt | C13: Ice & Water | D13: Panels
A14: 1 | B14: 20 | C14: 40 | D14: 270
A15: 2 | B15: 20 | C15: 40 | D15: 270
A16: 3 | B16: 20 | C16: 40 | D16: 270
A17: 4 | B17: 20 | C17: 40 | D17: 270
A18: 5 | B18: 20 | C18: 40 | D18: 270
A19: 6 | B19: 20 | C19: 40 | D19: 270
A20: 7 | B20: 22 | C20: 42 | D20: 280
A21: 8 | B21: 24 | C21: 44 | D21: 290
A22: 9 | B22: 26 | C22: 46 | D22: 300
A23: 10 | B23: 28 | C23: 48 | D23: 310
A24: 11 | B24: 30 | C24: 50 | D24: 320
A25: 12 | B25: 32 | C25: 52 | D25: 330
A26: Rates pull from the pitch typed on the bid (6/12 on TEMPLATE). PANELS start $270 on Zee-Lock — hand seam + machine for the double lock. Fab stays $40/sheet.

Sheet Bid (All-In Priced)
A1: SMS ROOFING — BERRIDGE ZEE-LOCK (DOUBLE-LOCK) • TEMPLATE — type the job into the blue cells • BID + TAKEOFF WALK-THROUGH
A2: Blue rows explain the line above with LIVE numbers. RED = raw/unrounded.
A4: 1 · PANEL TAKEOFF — quantity × length = linear feet (LF)
A5: ="A takeoff is counting what you install. Qty × Length = the LF that run needs. Sum all = total panel LF."
A6: Run | B6: Qty | C6: Length ft | I6: LF (Qty×Len)
A7: Panel LF (lump from takeoff) | B7: 1 | C7: 0 | I7: =B7*C7
A8: TOTAL PANEL LF | B8: =SUM(B7:B7) | I8: =SUM(I7:I7)
A9: ="All runs = "&B8&" panels = "&TEXT(I8,"#,##0.00")&" LF — drives coil, fab, labor, clips, vinyl. Add rows above as runs come in."
A11: 2 · PANEL SQUARES — LF into area (a ‘square’ = 100 sq ft)
A12: Panel coverage width (in) | F12: 16
A13: Panel SF = LF × (width ÷ 12) | F13: =I8*(F12/12)
A14: Panel SQUARES = SF ÷ 100 | F14: =F13/100
A15: ="Fab, labor, rivets price per square. "&TEXT(I8,"#,##0")&" LF × "&F12&"″÷12 = "&TEXT(F13,"#,##0")&" sf ÷100 = "&TEXT(F14,"0.00")&" sq."
A17: 3 · COIL — raw metal, full 1000′ (or 500′) rolls
A18: Item | B18: Need LF | C18: Coil LF | D18: Raw | E18: Coils | F18: $/coil | G18: Cost | I18: w/ tax
A19: Zee-Lock coil | B19: =I8 | C19: 500 | D19: =B19/C19 | E19: =ROUNDUP(D19,0) | F19: =C19*(20.875/12)*1.82 | G19: =E19*F19 | I19: =G19*1.0825
A20: ="Need "&TEXT(I8,"#,##0")&" LF ÷"&C19&" = "&TEXT(D19,"0.00")&" → "&E19&" coils. Price "&C19&"×(20.875÷12)×$1.82 = "&TEXT(F19,"$#,##0")&". Cost "&TEXT(G19,"$#,##0")&" +tax = "&TEXT(I19,"$#,##0.00")&"."
A22: 4 · FLAT METAL — drip, hip/ridge, Z flash from 48″×10′ sheets
A23: ="Cut from 48″×10′ sheets. 48 ÷ stretch-out = strips across; ×10′ = LF/sheet. LF ÷ that = sheets (round UP)."
A24: Piece | B24: LF | C24: Stretch-out in | D24: LF/sheet | E24: Raw sheets | F24: Sheets | G24: $/sheet | H24: Material | I24: Fab
A25: D-style drip edge | B25: 0 | C25: 9.5 | D25: =FLOOR(48/C25,1)*10 | E25: =B25/D25 | F25: =ROUNDUP(E25,0) | G25: 80 | H25: =F25*G25 | I25: =F25*40
A26: ="Drip: "&TEXT(B25,"#,##0")&" LF ÷ "&D25&" LF/sheet = "&TEXT(E25,"0.00")&" → "&F25&" sheets. Material "&F25&"×$80 = "&TEXT(H25,"$#,##0.00")&"; fab "&F25&"×$40 = "&TEXT(I25,"$#,##0.00")&"."
A27: Drip edge cleat (only if face > 4″)
A28: Drip edge cleat: PENDING Adam — only when the drip face is over 4″. LF + stretch-out to confirm; out of every total until then.
A29: Rake-edge cap (req. Z) | B29: 0 | C29: 12 | D29: =FLOOR(48/C29,1)*10 | E29: =B29/D29 | F29: =ROUNDUP(E29,0) | G29: 80 | H29: =F29*G29 | I29: =F29*40
A30: ="Rake-edge cap: "&TEXT(B29,"#,##0")&" LF ÷ "&D29&" LF/sheet = "&TEXT(E29,"0.00")&" → "&F29&" sheets. Material "&F29&"×$80 = "&TEXT(H29,"$#,##0.00")&"; fab "&F29&"×$40 = "&TEXT(I29,"$#,##0.00")&"."
A31: Rake edge cleat (galv) | B31: =B29 | C31: 5 | D31: =FLOOR(48/C31,1)*10 | E31: =B31/D31 | F31: =ROUNDUP(E31,0) | G31: 60 | H31: =F31*G31 | I31: =F31*40
A32: ="Rake edge cleat (follows rake-edge): "&TEXT(B31,"#,##0")&" LF ÷ "&D31&" LF/sheet = "&TEXT(E31,"0.00")&" → "&F31&" sheets. Material "&F31&"×$60 = "&TEXT(H31,"$#,##0.00")&"; fab "&F31&"×$40 = "&TEXT(I31,"$#,##0.00")&"."
A33: (W) Valley | B33: 0 | C33: 24 | D33: =FLOOR(48/C33,1)*10 | E33: =B33/D33 | F33: =ROUNDUP(E33,0) | G33: 80 | H33: =F33*G33 | I33: =F33*40
A34: ="(W) Valley: "&TEXT(B33,"#,##0")&" LF ÷ "&D33&" LF/sheet = "&TEXT(E33,"0.00")&" → "&F33&" sheets. Material "&F33&"×$80 = "&TEXT(H33,"$#,##0.00")&"; fab "&F33&"×$40 = "&TEXT(I33,"$#,##0.00")&"."
A35: (W) Valley cleat (both sides ×2) | B35: =B33*2 | C35: 3 | D35: =FLOOR(48/C35,1)*10 | E35: =B35/D35 | F35: =ROUNDUP(E35,0) | G35: 60 | H35: =F35*G35 | I35: =F35*40
A36: ="(W) Valley cleat (valley ×2 sides): "&TEXT(B35,"#,##0")&" LF ÷ "&D35&" LF/sheet = "&TEXT(E35,"0.00")&" → "&F35&" sheets. Material "&F35&"×$60 = "&TEXT(H35,"$#,##0.00")&"; fab "&F35&"×$40 = "&TEXT(I35,"$#,##0.00")&"."
A37: Hip/Ridge cap (req. Z ×2 sides) | B37: 0 | C37: 16 | D37: =FLOOR(48/C37,1)*10 | E37: =B37/D37 | F37: =ROUNDUP(E37,0) | G37: 80 | H37: =F37*G37 | I37: =F37*40
A38: ="Hip/Ridge: "&TEXT(B37,"#,##0")&" LF ÷ "&D37&" LF/sheet = "&TEXT(E37,"0.00")&" → "&F37&" sheets. Material "&F37&"×$80 = "&TEXT(H37,"$#,##0.00")&"; fab "&F37&"×$40 = "&TEXT(I37,"$#,##0.00")&"."
A39: Rake wall (req. Z + counterflashing) | B39: 0 | C39: 12 | D39: =FLOOR(48/C39,1)*10 | E39: =B39/D39 | F39: =ROUNDUP(E39,0) | G39: 80 | H39: =F39*G39 | I39: =F39*40
A40: ="Rake wall: "&TEXT(B39,"#,##0")&" LF ÷ "&D39&" LF/sheet = "&TEXT(E39,"0.00")&" → "&F39&" sheets. Material "&F39&"×$80 = "&TEXT(H39,"$#,##0.00")&"; fab "&F39&"×$40 = "&TEXT(I39,"$#,##0.00")&"."
A41: Head wall (req. Z + counterflashing)
A42: Head wall: none on TEMPLATE — sample/checklist row (works like rake wall: Z + counterflash). Fill LF + SO when a job has one.
A43: Curb — L flash (req. term-bar CF) | B43: 0 | C43: 16 | D43: =FLOOR(48/C43,1)*10 | E43: =B43/D43 | F43: =ROUNDUP(E43,0) | G43: 80 | H43: =F43*G43 | I43: =F43*40
A44: ="Curb L flash: "&TEXT(B43,"#,##0")&" LF ÷ "&D43&" LF/sheet = "&TEXT(E43,"0.00")&" → "&F43&" sheets. Material "&F43&"×$80 = "&TEXT(H43,"$#,##0.00")&"; fab "&F43&"×$40 = "&TEXT(I43,"$#,##0.00")&"."
...
